<?xml version="1.0" encoding="utf-8"?>
<!-- This URDF was automatically created by SolidWorks to URDF Exporter! Originally created by Stephen Brawner (brawner@gmail.com) 
     Commit Version: 1.4.4-24-g24328f6  Build Version: 1.5.7084.36479
     For more information, please see http://wiki.ros.org/sw_urdf_exporter -->
<robot
  name="chyPapa4">
  <link
    name="base_link">
    <inertial>
      <origin
        xyz="0.020248 0.018724 0.022774"
        rpy="0 0 0" />
      <mass
        value="0.042074" />
      <inertia
        ixx="5.8864E-06"
        ixy="1.9421E-06"
        ixz="5.1006E-06"
        iyy="2.8358E-05"
        iyz="-4.7525E-07"
        izz="2.5482E-05" />
    </inertial>
    <visual>
      <origin
        xyz="0 0 0"
        rpy="0 0 0" />
      <geometry>
        <mesh
          filename="package://chyPapa4/meshes/base_link.STL" />
      </geometry>
      <material
        name="">
        <color
          rgba="1 1 1 1" />
      </material>
    </visual>
    <collision>
      <origin
        xyz="0 0 0"
        rpy="0 0 0" />
      <geometry>
        <mesh
          filename="package://chyPapa4/meshes/base_link.STL" />
      </geometry>
    </collision>
  </link>
  <link
    name="Link_Shoulder_fl">
    <inertial>
      <origin
        xyz="0.00011744 0.0012019 0.01"
        rpy="0 0 0" />
      <mass
        value="0.034142" />
      <inertia
        ixx="6.1579E-06"
        ixy="-8.4359E-08"
        ixz="2.8079E-11"
        iyy="5.8407E-06"
        iyz="-1.5388E-10"
        izz="9.772E-06" />
    </inertial>
    <visual>
      <origin
        xyz="0 0 0"
        rpy="0 0 0" />
      <geometry>
        <mesh
          filename="package://chyPapa4/meshes/Link_Shoulder_fl.STL" />
      </geometry>
      <material
        name="">
        <color
          rgba="1 1 1 1" />
      </material>
    </visual>
    <collision>
      <origin
        xyz="0 0 0"
        rpy="0 0 0" />
      <geometry>
        <mesh
          filename="package://chyPapa4/meshes/Link_Shoulder_fl.STL" />
      </geometry>
    </collision>
  </link>
  <joint
    name="Joint_Shoulder_Body_fl"
    type="revolute">
    <origin
      xyz="-0.040882 -0.025286 -0.0003707"
      rpy="1.5708 0 0" />
    <parent
      link="base_link" />
    <child
      link="Link_Shoulder_fl" />
    <axis
      xyz="0 0 1" />
    <limit
      lower="-1.5"
      upper="1.5"
      effort="100"
      velocity="0" />
    <safety_controller
      k_velocity="0" />
  </joint>
</robot>