<?xml version="1.0" encoding="utf-8"?>
<!-- This URDF was automatically created by SolidWorks to URDF Exporter! Originally created by Stephen Brawner (brawner@gmail.com) 
     Commit Version: 1.6.0-1-g15f4949  Build Version: 1.6.7594.29634
     For more information, please see http://wiki.ros.org/sw_urdf_exporter -->
<robot
  name="chyPapa4">
  <link
    name="base_link">
    <inertial>
      <origin
        xyz="0.0202481629823698 0.0187243756673782 0.0227744974719993"
        rpy="0 0 0" />
      <mass
        value="0.0420735853495988" />
      <inertia
        ixx="5.88637369495906E-06"
        ixy="1.94214625037226E-06"
        ixz="5.10059645854758E-06"
        iyy="2.83575795096436E-05"
        iyz="-4.75247080484324E-07"
        izz="2.54823614392689E-05" />
    </inertial>
    <visual>
      <origin
        xyz="0 0 0"
        rpy="0 0 0" />
      <geometry>
        <mesh
          filename="package://chyPapa4/meshes/base_link.STL" />
      </geometry>
      <material
        name="">
        <color
          rgba="1 1 1 1" />
      </material>
    </visual>
    <collision>
      <origin
        xyz="0 0 0"
        rpy="0 0 0" />
      <geometry>
        <mesh
          filename="package://chyPapa4/meshes/base_link.STL" />
      </geometry>
    </collision>
  </link>
  <link
    name="Link_Shoulder_fl">
    <inertial>
      <origin
        xyz="-0.00120189420024862 -0.000117441816613433 -0.0100002220463185"
        rpy="0 0 0" />
      <mass
        value="0.0341422557519" />
      <inertia
        ixx="5.84073892863087E-06"
        ixy="-8.43586991661572E-08"
        ixz="-1.53883232331005E-10"
        iyy="6.15792129214538E-06"
        iyz="2.80792760151049E-11"
        izz="9.77204160815347E-06" />
    </inertial>
    <visual>
      <origin
        xyz="0 0 0"
        rpy="0 0 0" />
      <geometry>
        <mesh
          filename="package://chyPapa4/meshes/Link_Shoulder_fl.STL" />
      </geometry>
      <material
        name="">
        <color
          rgba="1 1 1 1" />
      </material>
    </visual>
    <collision>
      <origin
        xyz="0 0 0"
        rpy="0 0 0" />
      <geometry>
        <mesh
          filename="package://chyPapa4/meshes/Link_Shoulder_fl.STL" />
      </geometry>
    </collision>
  </link>
  <joint
    name="Joint_Shoulder_Body_fl"
    type="revolute">
    <origin
      xyz="-0.040882 -0.025286 -0.0003707"
      rpy="1.5708 1.5708 0" />
    <parent
      link="base_link" />
    <child
      link="Link_Shoulder_fl" />
    <axis
      xyz="-1 0 0" />
    <limit
      lower="-1.5"
      upper="1.5"
      effort="100"
      velocity="0" />
    <safety_controller
      k_velocity="0" />
  </joint>
</robot>