<?xml version="1.0" encoding="utf-8"?>
<!-- This URDF was automatically created by SolidWorks to URDF Exporter! Originally created by Stephen Brawner (brawner@gmail.com) 
     Commit Version: 1.6.0-1-g15f4949  Build Version: 1.6.7594.29634
     For more information, please see http://wiki.ros.org/sw_urdf_exporter -->
<robot
  name="chyPapa4">
  <link
    name="base_link">
    <inertial>
      <origin
        xyz="-0.0281544850256863 0.0104270421891137 -0.0434823068140249"
        rpy="0 0 0" />
      <mass
        value="0.108265195096751" />
      <inertia
        ixx="0.000166073388474921"
        ixy="3.01904595576301E-07"
        ixz="5.0421919488782E-06"
        iyy="0.000163044159957564"
        iyz="-8.84990834747846E-06"
        izz="2.15813542605032E-05" />
    </inertial>
    <visual>
      <origin
        xyz="0 0 0"
        rpy="0 0 0" />
      <geometry>
        <mesh
          filename="package://chyPapa4/meshes/base_link.STL" />
      </geometry>
      <material
        name="">
        <color
          rgba="1 1 1 1" />
      </material>
    </visual>
    <collision>
      <origin
        xyz="0 0 0"
        rpy="0 0 0" />
      <geometry>
        <mesh
          filename="package://chyPapa4/meshes/base_link.STL" />
      </geometry>
    </collision>
  </link>
  <link
    name="Link_Shoulder_fl">
    <inertial>
      <origin
        xyz="-0.0098767 -0.00034056 -0.021798"
        rpy="0 0 0" />
      <mass
        value="0.034142" />
      <inertia
        ixx="6.1622E-06"
        ixy="-1.2442E-07"
        ixz="-8.4314E-08"
        iyy="9.7678E-06"
        iyz="-2.7514E-09"
        izz="5.8407E-06" />
    </inertial>
    <visual>
      <origin
        xyz="0 0 0"
        rpy="0 0 0" />
      <geometry>
        <mesh
          filename="package://chyPapa4/meshes/Link_Shoulder_fl.STL" />
      </geometry>
      <material
        name="">
        <color
          rgba="1 1 1 1" />
      </material>
    </visual>
    <collision>
      <origin
        xyz="0 0 0"
        rpy="0 0 0" />
      <geometry>
        <mesh
          filename="package://chyPapa4/meshes/Link_Shoulder_fl.STL" />
      </geometry>
    </collision>
  </link>
  <joint
    name="Joint_Shoulder_Body_fl"
    type="revolute">
    <origin
      xyz="-0.030882 -0.035286 0.022629"
      rpy="0 0 -0.034445" />
    <parent
      link="base_link" />
    <child
      link="Link_Shoulder_fl" />
    <axis
      xyz="0 0 1" />
    <limit
      lower="-1.5"
      upper="1.5"
      effort="100"
      velocity="0" />
    <safety_controller
      k_velocity="0" />
  </joint>
</robot>