<?xml version="1.0" encoding="utf-8"?>
<!-- This URDF was automatically created by SolidWorks to URDF Exporter! Originally created by Stephen Brawner (brawner@gmail.com) 
     Commit Version: 1.6.0-1-g15f4949  Build Version: 1.6.7594.29634
     For more information, please see http://wiki.ros.org/sw_urdf_exporter -->
<robot
  name="chyPapa4">
  <link
    name="base_link">
    <inertial>
      <origin
        xyz="-0.0110950761202187 -3.46944695195361E-18 0.00763828337499935"
        rpy="0 0 0" />
      <mass
        value="0.0420735853495988" />
      <inertia
        ixx="2.83575795096436E-05"
        ixy="3.02322461397396E-21"
        ixz="-1.99944788512827E-06"
        iyy="2.67304876167845E-05"
        iyz="-5.9292306307801E-21"
        izz="4.63824751744344E-06" />
    </inertial>
    <visual>
      <origin
        xyz="0 0 0"
        rpy="0 0 0" />
      <geometry>
        <mesh
          filename="package://chyPapa4/meshes/base_link.STL" />
      </geometry>
      <material
        name="">
        <color
          rgba="1 1 1 1" />
      </material>
    </visual>
    <collision>
      <origin
        xyz="0 0 0"
        rpy="0 0 0" />
      <geometry>
        <mesh
          filename="package://chyPapa4/meshes/base_link.STL" />
      </geometry>
    </collision>
  </link>
  <link
    name="Link_Shoulder_fl">
    <inertial>
      <origin
        xyz="-0.00120189420024862 -0.000117441816613433 -0.0100002220463185"
        rpy="0 0 0" />
      <mass
        value="0.0341422557519" />
      <inertia
        ixx="5.84073892863087E-06"
        ixy="-8.43586991661572E-08"
        ixz="-1.5388323233099E-10"
        iyy="6.15792129214538E-06"
        iyz="2.80792760151051E-11"
        izz="9.77204160815347E-06" />
    </inertial>
    <visual>
      <origin
        xyz="0 0 0"
        rpy="0 0 0" />
      <geometry>
        <mesh
          filename="package://chyPapa4/meshes/Link_Shoulder_fl.STL" />
      </geometry>
      <material
        name="">
        <color
          rgba="1 1 1 1" />
      </material>
    </visual>
    <collision>
      <origin
        xyz="0 0 0"
        rpy="0 0 0" />
      <geometry>
        <mesh
          filename="package://chyPapa4/meshes/Link_Shoulder_fl.STL" />
      </geometry>
    </collision>
  </link>
  <joint
    name="Joint_Shoulder_Body_fl"
    type="revolute">
    <origin
      xyz="0.008 0.01209 -0.052337"
      rpy="-1.3308 0 0" />
    <parent
      link="base_link" />
    <child
      link="Link_Shoulder_fl" />
    <axis
      xyz="-1 0 0" />
    <limit
      lower="-1.5"
      upper="1.5"
      effort="100"
      velocity="0" />
    <safety_controller
      k_velocity="0" />
  </joint>
</robot>