<?xml version="1.0" encoding="utf-8"?>
<!-- This URDF was automatically created by SolidWorks to URDF Exporter! Originally created by Stephen Brawner (brawner@gmail.com) 
     Commit Version: 1.6.0-1-g15f4949  Build Version: 1.6.7594.29634
     For more information, please see http://wiki.ros.org/sw_urdf_exporter -->
<robot
  name="chyPapa5">
  <link
    name="base_link">
    <inertial>
      <origin
        xyz="-1.76103229128108E-17 0.000369441212972375 -0.011864156308418"
        rpy="0 0 0" />
      <mass
        value="0.301530504160963" />
      <inertia
        ixx="0.000506923634750398"
        ixy="-1.71966331110651E-06"
        ixz="4.67346607234249E-10"
        iyy="0.00035267121080194"
        iyz="-2.86244231269215E-09"
        izz="0.000624936520803351" />
    </inertial>
    <visual>
      <origin
        xyz="0 0 0"
        rpy="0 0 0" />
      <geometry>
        <mesh
          filename="package://chyPapa5/meshes/base_link.STL" />
      </geometry>
      <material
        name="">
        <color
          rgba="0.792156862745098 0.819607843137255 0.929411764705882 1" />
      </material>
    </visual>
    <collision>
      <origin
        xyz="0 0 0"
        rpy="0 0 0" />
      <geometry>
        <mesh
          filename="package://chyPapa5/meshes/base_link.STL" />
      </geometry>
    </collision>
  </link>
  <joint
    name="Joint_Shoulder_rf"
    type="revolute">
    <origin
      xyz="0.0725 0.019059 0.035943"
      rpy="3.1416 1.5708 0" />
    <parent
      link="base_link" />
    <child
      link="Link_Shoulder_rf" />
    <axis
      xyz="0 0 1" />
    <limit
      lower="0.5"
      upper="1.5"
      effort="100"
      velocity="0" />
  </joint>
  <link
    name="Link_Shoulder_rf">
    <inertial>
      <origin
        xyz="-0.011334 0.011623 -0.025779"
        rpy="0 0 0" />
      <mass
        value="0.09598" />
      <inertia
        ixx="2.2103E-05"
        ixy="-2.3403E-06"
        ixz="-2.499E-07"
        iyy="3.2349E-05"
        iyz="-1.2485E-06"
        izz="2.0828E-05" />
    </inertial>
    <visual>
      <origin
        xyz="0 0 0"
        rpy="0 0 0" />
      <geometry>
        <mesh
          filename="package://chyPapa5/meshes/Link_Shoulder_rf.STL" />
      </geometry>
      <material
        name="">
        <color
          rgba="0.79216 0.81961 0.93333 1" />
      </material>
    </visual>
    <collision>
      <origin
        xyz="0 0 0"
        rpy="0 0 0" />
      <geometry>
        <mesh
          filename="package://chyPapa5/meshes/Link_Shoulder_rf.STL" />
      </geometry>
    </collision>
  </link>
  <joint
    name="Joint_Shoulder_rf"
    type="revolute">
    <origin
      xyz="0.0725 0.019059 0.035943"
      rpy="3.1416 1.5708 0" />
    <parent
      link="base_link" />
    <child
      link="Link_Shoulder_rf" />
    <axis
      xyz="0 0 1" />
    <limit
      lower="0.5"
      upper="1.5"
      effort="0"
      velocity="0" />
  </joint>
</robot>