<?xml version="1.0" encoding="utf-8"?>
<!-- This URDF was automatically created by SolidWorks to URDF Exporter! Originally created by Stephen Brawner (brawner@gmail.com) 
     Commit Version: 1.6.0-1-g15f4949  Build Version: 1.6.7594.29634
     For more information, please see http://wiki.ros.org/sw_urdf_exporter -->
<robot
  name="chyPapa5">
  <link
    name="base_link">
    <inertial>
      <origin
        xyz="-1.20328311049649E-17 0.000369441212972375 -0.011864156308418"
        rpy="0 0 0" />
      <mass
        value="0.301530504160963" />
      <inertia
        ixx="0.000506923634750398"
        ixy="-1.71966331110652E-06"
        ixz="4.67346607231123E-10"
        iyy="0.00035267121080194"
        iyz="-2.86244231269397E-09"
        izz="0.000624936520803351" />
    </inertial>
    <visual>
      <origin
        xyz="0 0 0"
        rpy="0 0 0" />
      <geometry>
        <mesh
          filename="package://chyPapa5/meshes/base_link.STL" />
      </geometry>
      <material
        name="">
        <color
          rgba="0.792156862745098 0.819607843137255 0.929411764705882 1" />
      </material>
    </visual>
    <collision>
      <origin
        xyz="0 0 0"
        rpy="0 0 0" />
      <geometry>
        <mesh
          filename="package://chyPapa5/meshes/base_link.STL" />
      </geometry>
    </collision>
  </link>
  <link
    name="link_shoulder_rf">
    <inertial>
      <origin
        xyz="-0.010359 -0.0125 0.029779"
        rpy="0 0 0" />
      <mass
        value="0.09598" />
      <inertia
        ixx="2.1794E-05"
        ixy="1.4856E-06"
        ixz="3.4986E-07"
        iyy="3.2658E-05"
        iyz="-1.2243E-06"
        izz="2.0828E-05" />
    </inertial>
    <visual>
      <origin
        xyz="0 0 0"
        rpy="0 0 0" />
      <geometry>
        <mesh
          filename="package://chyPapa5/meshes/link_shoulder_rf.STL" />
      </geometry>
      <material
        name="">
        <color
          rgba="0.79216 0.81961 0.93333 1" />
      </material>
    </visual>
    <collision>
      <origin
        xyz="0 0 0"
        rpy="0 0 0" />
      <geometry>
        <mesh
          filename="package://chyPapa5/meshes/link_shoulder_rf.STL" />
      </geometry>
    </collision>
  </link>
  <joint
    name="joint_shoulder_rf"
    type="revolute">
    <origin
      xyz="0.0685 0.019059 0.035943"
      rpy="-1.5708 1.49 -1.5708" />
    <parent
      link="base_link" />
    <child
      link="link_shoulder_rf" />
    <axis
      xyz="0 0 -1" />
    <limit
      lower="1.5"
      upper="0.5"
      effort="100"
      velocity="0" />
  </joint>
</robot>