<?xml version="1.0" encoding="utf-8"?>
<!-- This URDF was automatically created by SolidWorks to URDF Exporter! Originally created by Stephen Brawner (brawner@gmail.com) 
     Commit Version: 1.6.0-1-g15f4949  Build Version: 1.6.7594.29634
     For more information, please see http://wiki.ros.org/sw_urdf_exporter -->
<robot
  name="chyPapa5">
  <link
    name="base_link">
    <inertial>
      <origin
        xyz="-1.4383E-17 0.00036944 0.011864"
        rpy="0 0 0" />
      <mass
        value="0.30153" />
      <inertia
        ixx="0.00050692"
        ixy="1.7197E-06"
        ixz="4.6735E-10"
        iyy="0.00035267"
        iyz="2.8624E-09"
        izz="0.00062494" />
    </inertial>
    <visual>
      <origin
        xyz="0 0 0"
        rpy="0 0 0" />
      <geometry>
        <mesh
          filename="package://chyPapa5/meshes/base_link.STL" />
      </geometry>
      <material
        name="">
        <color
          rgba="0.79216 0.81961 0.93333 1" />
      </material>
    </visual>
    <collision>
      <origin
        xyz="0 0 0"
        rpy="0 0 0" />
      <geometry>
        <mesh
          filename="package://chyPapa5/meshes/base_link.STL" />
      </geometry>
    </collision>
  </link>
  <link
    name="Link_Shoulder_rf">
    <inertial>
      <origin
        xyz="-0.0124 0.012221 0.029708"
        rpy="0 0 0" />
      <mass
        value="0.09598" />
      <inertia
        ixx="3.2658E-05"
        ixy="-1.2243E-06"
        ixz="-1.4856E-06"
        iyy="2.0828E-05"
        iyz="-3.4986E-07"
        izz="2.1794E-05" />
    </inertial>
    <visual>
      <origin
        xyz="0 0 0"
        rpy="0 0 0" />
      <geometry>
        <mesh
          filename="package://chyPapa5/meshes/Link_Shoulder_rf.STL" />
      </geometry>
      <material
        name="">
        <color
          rgba="0.79216 0.81961 0.93333 1" />
      </material>
    </visual>
    <collision>
      <origin
        xyz="0 0 0"
        rpy="0 0 0" />
      <geometry>
        <mesh
          filename="package://chyPapa5/meshes/Link_Shoulder_rf.STL" />
      </geometry>
    </collision>
  </link>
  <joint
    name="Joint_Shoulder_rf"
    type="revolute">
    <origin
      xyz="0.0685 -0.019304 -0.034561"
      rpy="-1.5708 0.034331 -1.5708" />
    <parent
      link="base_link" />
    <child
      link="Link_Shoulder_rf" />
    <axis
      xyz="0 0 -1" />
    <limit
      lower="1.5"
      upper="0.5"
      effort="100"
      velocity="0" />
  </joint>
</robot>