<?xml version="1.0" encoding="utf-8"?>
<!-- This URDF was automatically created by SolidWorks to URDF Exporter! Originally created by Stephen Brawner (brawner@gmail.com) 
     Commit Version: 1.6.0-1-g15f4949  Build Version: 1.6.7594.29634
     For more information, please see http://wiki.ros.org/sw_urdf_exporter -->
<robot
  name="chyPapa5">
  <link
    name="base_link">
    <inertial>
      <origin
        xyz="0.00018262 -0.00036446 -0.011879"
        rpy="0 0 0" />
      <mass
        value="0.30228" />
      <inertia
        ixx="0.00050827"
        ixy="1.672E-06"
        ixz="-5.0357E-08"
        iyy="0.00035288"
        iyz="-1.673E-09"
        izz="0.00062639" />
    </inertial>
    <visual>
      <origin
        xyz="0 0 0"
        rpy="0 0 0" />
      <geometry>
        <mesh
          filename="package://chyPapa5/meshes/base_link.STL" />
      </geometry>
      <material
        name="">
        <color
          rgba="0.79216 0.81961 0.93333 1" />
      </material>
    </visual>
    <collision>
      <origin
        xyz="0 0 0"
        rpy="0 0 0" />
      <geometry>
        <mesh
          filename="package://chyPapa5/meshes/base_link.STL" />
      </geometry>
    </collision>
  </link>
  <link
    name="Link_Shoulder_le">
    <inertial>
      <origin
        xyz="-0.01228 -0.01264 -0.023521"
        rpy="0 0 0" />
      <mass
        value="0.10024" />
      <inertia
        ixx="3.6483E-05"
        ixy="7.8808E-07"
        ixz="1.2662E-06"
        iyy="2.4436E-05"
        iyz="-2.9444E-07"
        izz="2.4052E-05" />
    </inertial>
    <visual>
      <origin
        xyz="0 0 0"
        rpy="0 0 0" />
      <geometry>
        <mesh
          filename="package://chyPapa5/meshes/Link_Shoulder_le.STL" />
      </geometry>
      <material
        name="">
        <color
          rgba="0.79216 0.81961 0.93333 1" />
      </material>
    </visual>
    <collision>
      <origin
        xyz="0 0 0"
        rpy="0 0 0" />
      <geometry>
        <mesh
          filename="package://chyPapa5/meshes/Link_Shoulder_le.STL" />
      </geometry>
    </collision>
  </link>
  <joint
    name="Joint_Shoulder_le"
    type="revolute">
    <origin
      xyz="-0.071696 -0.03752 -0.019059"
      rpy="-1.5708 1.5707 -1.5489" />
    <parent
      link="base_link" />
    <child
      link="Link_Shoulder_le" />
    <axis
      xyz="0 0 1" />
    <limit
      lower="-0.5"
      upper="1.5"
      effort="100"
      velocity="0" />
  </joint>
</robot>