<?xml version="1.0" encoding="utf-8"?>
<!-- This URDF was automatically created by SolidWorks to URDF Exporter! Originally created by Stephen Brawner (brawner@gmail.com) 
     Commit Version: 1.4.4-24-g24328f6  Build Version: 1.5.7084.36479
     For more information, please see http://wiki.ros.org/sw_urdf_exporter -->
<robot
  name="装配体2.SLDASM">
  <link
    name="base_link">
    <inertial>
      <origin
        xyz="-0.0502216761325691 0.0308703259893273 -0.00242371771234083"
        rpy="0 0 0" />
      <mass
        value="0.0207864363086098" />
      <inertia
        ixx="6.27146359614103E-06"
        ixy="3.91384878570614E-08"
        ixz="-1.74281939934301E-07"
        iyy="6.22523670823708E-06"
        iyz="-2.24464498340632E-07"
        izz="1.02843302597723E-05" />
    </inertial>
    <visual>
      <origin
        xyz="0 0 0"
        rpy="0 0 0" />
      <geometry>
        <mesh
          filename="package://装配体2.SLDASM/meshes/base_link.STL" />
      </geometry>
      <material
        name="">
        <color
          rgba="1 1 1 1" />
      </material>
    </visual>
    <collision>
      <origin
        xyz="0 0 0"
        rpy="0 0 0" />
      <geometry>
        <mesh
          filename="package://装配体2.SLDASM/meshes/base_link.STL" />
      </geometry>
    </collision>
  </link>
  <link
    name="Empty_Link">
    <inertial>
      <origin
        xyz="0.00278573313529829 0.108642875961877 0.0132022573580459"
        rpy="0 0 0" />
      <mass
        value="0.108265195096751" />
      <inertia
        ixx="0.000165610728957086"
        ixy="9.5948038385654E-06"
        ixz="5.81350225609557E-07"
        iyy="2.20440137783383E-05"
        iyz="-8.83595247037819E-06"
        izz="0.000163044159957564" />
    </inertial>
    <visual>
      <origin
        xyz="0 0 0"
        rpy="0 0 0" />
      <geometry>
        <mesh
          filename="package://装配体2.SLDASM/meshes/Empty_Link.STL" />
      </geometry>
      <material
        name="">
        <color
          rgba="1 1 1 1" />
      </material>
    </visual>
    <collision>
      <origin
        xyz="0 0 0"
        rpy="0 0 0" />
      <geometry>
        <mesh
          filename="package://装配体2.SLDASM/meshes/Empty_Link.STL" />
      </geometry>
    </collision>
  </link>
  <joint
    name="joint_arm_shelft"
    type="revolute">
    <origin
      xyz="-0.050797 0.02 0.0030326"
      rpy="0 0 3.1416" />
    <parent
      link="base_link" />
    <child
      link="Empty_Link" />
    <axis
      xyz="0 0 -1" />
    <limit
      lower="-1.57"
      upper="1.57"
      effort="0"
      velocity="0" />
    <safety_controller
      k_velocity="0" />
  </joint>
</robot>